 <?xml version="1.0"?>
 <robot name="simple_arm">
  <link name="base_link">
    <inertial>
      <mass value="0.01" />
      <origin xyz="0 0 0" />
      <inertia ixx="0.001" ixy="0.0" ixz="0.0" iyy="0.001" iyz="0.0" izz="0.001" />
    </inertial>
   </link>

  <link name="arm_body">
    <visual>
      <geometry>
        <mesh filename="mesh/arm_meters.stl"/>
      </geometry>
    </visual>
    <collision>
      <geometry>
        <mesh filename="mesh/arm_meters.stl"/>
      </geometry>
    </collision>
    <inertial>
      <mass value="2." />
      <origin xyz="0.01415 0.000156 0.0023"/>
      <inertia ixx="8.099999999999999e-05" ixy="3.6e-05" ixz="1.3552527156068806e-21" iyy="0.0003076666666666667" iyz="-0.0" izz="0.00033866666666666664" />
    </inertial>
  </link>
 
  <joint name="joint_0" type="revolute">
    <parent link="base_link"/>
    <child link="arm_body"/>
    <origin xyz="0 0 0" rpy="0 0 0" />
    <axis xyz="0 0 1"/>
    <limit effort="1000.0" lower="-2.0" upper="2.0" velocity="1"/>
  </joint>
 
   <link name="tool0">
    <inertial>
      <mass value="0.0"/>
      <origin rpy="0 0 0" xyz="0 0 0"/>
      <inertia ixx="0.0" ixy="0.0" ixz="0.0" iyy="0.0" iyz="0.0" izz="0.0"/>
    </inertial>
  </link>

  <joint name="arm_body_tool0_fixed_joint" type="fixed">
    <origin xyz="0.07 0.0 0.0" rpy="0 0 0" />
    <parent link="arm_body"/>
    <child link="tool0"/>
  </joint>

</robot>