<?xml version="1.0" encoding="utf-8"?>
<robot name="svh">
  <link name="base_link"/>

  <joint name="root_joint" type="fixed">
    <parent link="base_link"/>
    <child link="right_hand_base_link"/>
    <origin xyz="0 0 0" rpy="0 0 -1.57"/>
  </joint>

  <link name="right_hand_base_link">
    <origin xyz="0 0 0" rpy="0 0 0"/>
    <visual>
      <origin xyz="0 0 -0.032"/>
      <geometry>
        <mesh filename="meshes/v2/base10.obj"/>
      </geometry>
    </visual>
    <collision>
      <origin xyz="0 0 -0.032"/>
      <geometry>
        <mesh filename="meshes/v2/base10.obj"/>
      </geometry>
    </collision>
    <inertial>
      <mass value="0.57743"/>
      <origin xyz="0.0 -2.3e-05 0.139371"/>
      <inertia ixx="0.04725" ixy="-0.0" ixz="-0.0" iyy="0.04717" iyz="0.0" izz="0.07606" />
    </inertial>
  </link>
  
  <link name="right_hand_d">
    <inertial>
      <mass value="0.01" />
      <origin xyz="0 0 0" />
      <inertia ixx="0.001" ixy="0.0" ixz="0.0" iyy="0.001" iyz="0.0" izz="0.001" />
    </inertial>
  </link>

  <link name="right_hand_h">
    <inertial>
      <mass value="0.01" />
      <origin xyz="0 0 0" />
      <inertia ixx="0.001" ixy="0.0" ixz="0.0" iyy="0.001" iyz="0.0" izz="0.001" />
    </inertial>
  </link>

  <link name="right_hand_d2">
    <inertial>
      <mass value="0.01" />
      <origin xyz="0 0 0" />
      <inertia ixx="0.001" ixy="0.0" ixz="0.0" iyy="0.001" iyz="0.0" izz="0.001" />
    </inertial>
  </link>

  <!-- LENGTH NOT FOUND IN DATASHEET! GUESSED!!! -->
  <link name="right_hand_e1">
    <visual>
      <origin rpy="0 0 0" xyz="0 0.01313 0"/>
      <geometry>
        <mesh filename="meshes/v2/h10.obj" scale="1 1 1"/>
      </geometry>
    </visual>
    <collision>
      <origin rpy="0 0 0" xyz="0 0.01313 0"/>
      <geometry>
        <mesh filename="meshes/v2/h10.obj" scale="1 1 1"/>
      </geometry>
    </collision>
    <inertial>
      <mass value="0.01" />
      <origin xyz="0 0 0" />
      <inertia ixx="0.001" ixy="0.0" ixz="0.0" iyy="0.001" iyz="0.0" izz="0.001" />
    </inertial>
  </link>

  <!-- LENGTH NOT FOUND IN DATASHEET! GUESSED!!! -->
  <link name="right_hand_e2">
    <visual>
      <origin xyz="-0.0007 0 -0.01002" />
      <geometry>
        <mesh filename="meshes/v2/h11.obj" scale="1 1 1"/>
      </geometry>
    </visual>
    <collision>
      <origin xyz="-0.0007 0 -0.01002" />
      <geometry>
        <mesh filename="meshes/v2/h11.obj" scale="1 1 1"/>
      </geometry>
    </collision>
    <inertial>
      <mass value="0.46184"/>
      <origin xyz="0.145071 -0.037868 0.323449"/>
      <inertia ixx="0.01908" ixy="-0.00121" ixz="-0.00011" iyy="0.01704" iyz="0.00277" izz="0.00862"/>
    </inertial>
  </link>

  <link name="right_hand_e3">
    <inertial>
      <mass value="0.01" />
      <origin xyz="0 0 0" />
      <inertia ixx="0.001" ixy="0.0" ixz="0.0" iyy="0.001" iyz="0.0" izz="0.001" />
    </inertial>
  </link>

  <link name="right_hand_e">
  </link>

  <link name="right_hand_e4">
    <inertial>
      <mass value="0.01" />
      <origin xyz="0 0 0" />
      <inertia ixx="0.001" ixy="0.0" ixz="0.0" iyy="0.001" iyz="0.0" izz="0.001" />
    </inertial>
  </link>

    <link name="right_hand_e5">
    <inertial>
      <mass value="0.01" />
      <origin xyz="0 0 0" />
      <inertia ixx="0.001" ixy="0.0" ixz="0.0" iyy="0.001" iyz="0.0" izz="0.001" />
    </inertial>
  </link>

  <!-- THUMB LINKS -->
  <link name="right_hand_z">
    <visual>
      <origin xyz="0 0 0.02442"/>
      <geometry>
        <mesh filename="meshes/v2/d10.obj" scale="1 1 1"/>
      </geometry>
    </visual>
    <collision>
      <origin xyz="0 0 0.02442"/>
      <geometry>
        <mesh filename="meshes/v2/d10.obj" scale="1 1 1"/>
      </geometry>
    </collision>
    <inertial>
      <mass value="0.0739"/>
      <origin xyz="0.0 0.002024 0.178636"/>
      <inertia ixx="0.00103" ixy="-0.0" ixz="-0.0" iyy="0.00165" iyz="4e-05" izz="0.00111"/>
    </inertial>
  </link>

  <link name="right_hand_virtual_a">
    <inertial>
      <mass value="0.01" />
      <origin xyz="0 0 0" />
      <inertia ixx="0.001" ixy="0.0" ixz="0.0" iyy="0.001" iyz="0.0" izz="0.001" />
    </inertial>
  </link>

  <link name="right_hand_a">
    <visual>
      <geometry>
        <mesh filename="meshes/v2/d11.obj" scale="1 1 1"/>
      </geometry>
    </visual>
    <collision>
      <geometry>
        <mesh filename="meshes/v2/d11.obj" scale="1 1 1"/>
      </geometry>
    </collision>
    <inertial>
      <mass value="0.41222"/>
      <origin xyz="0.240205 0.010733 0.00019"/>
      <inertia ixx="0.00413" ixy="0.00073" ixz="-0.0" iyy="0.01679" iyz="0.0" izz="0.01796"/>
    </inertial>
  </link>

  <link name="right_hand_b">
    <visual>
      <geometry>
        <mesh filename="meshes/v2/d12.obj" scale="1 1 1"/>
      </geometry>
    </visual>
    <collision>
      <geometry>
        <mesh filename="meshes/v2/d12.obj" scale="1 1 1"/>
      </geometry>
    </collision>
    <inertial>
      <mass value="0.08224"/>
      <origin xyz="0.123157 -0.008382 -2.7e-05"/>
      <inertia ixx="0.00089" ixy="5e-05" ixz="0.0" iyy="0.00139" iyz="0.0" izz="0.00103"/>
    </inertial>
  </link>

  <link name="right_hand_c">
    <visual>
      <geometry>
        <mesh filename="meshes/v2/d13.obj" scale="1 1 1"/>
      </geometry>
    </visual>
    <collision>
      <geometry>
        <mesh filename="meshes/v2/d13.obj" scale="1 1 1"/>
      </geometry>
    </collision>
    <inertial>
      <mass value="0.06198"/>
      <origin xyz="0.113729 0.01094 0.0"/>
      <inertia ixx="0.00025" ixy="-0.0" ixz="-0.0" iyy="0.00051" iyz="0.0" izz="0.00052"/>
    </inertial>
  </link>

  <!-- INDEX FINGER LINKS -->
  <link name="right_hand_virtual_l">
    <visual>
      <origin xyz="0 0 0.01321"/>
      <geometry>
        <mesh filename="meshes/v2/f10.obj"/>
      </geometry>
    </visual>
    <collision>
      <origin xyz="0 0 0.01321"/>
      <geometry>
        <mesh filename="meshes/v2/f10.obj"/>
      </geometry>
    </collision>

  <!-- <inertial>
    <mass value="0.02383"/>
    <origin xyz="0.003634 0.000206 -0.09885"/>
    <inertia ixx="0.00021" ixy="-0.0" ixz="-1e-05" iyy="0.00011" iyz="-0.0" izz="0.00019"/>
  </inertial>   -->
  <!-- Initial values make the inertia mass matrix not invertible as below floating point precision 
  for determinant, so we assume a default regularized version... -->
  <inertial>
    <mass value="0.02383" />
      <origin xyz="0.003634 0.000206 -0.09885"/>
    <inertia ixx="0.001" ixy="0.0" ixz="0.0" iyy="0.001" iyz="0.0" izz="0.001" />
  </inertial>
  </link>

  <link name="right_hand_l">
    <visual>
      <geometry>
        <mesh filename="meshes/v2/f11.obj"/>
      </geometry>
    </visual>
    <collision>
      <geometry>
        <mesh filename="meshes/v2/f11.obj"/>
      </geometry>
    </collision>
    <inertial>
      <mass value="0.13003"/>
      <origin xyz="0.261673 0.003521 0.0"/>
      <inertia ixx="0.00051" ixy="-3e-05" ixz="0.0" iyy="0.00335" iyz="-0.0" izz="0.00344"/>
    </inertial>
  </link>

  <link name="right_hand_p">
    <visual>
      <geometry>
        <mesh filename="meshes/v2/f12.obj"/>
      </geometry>
    </visual>
    <collision>
      <geometry>
        <mesh filename="meshes/v2/f12.obj"/>
      </geometry>
    </collision>
    <inertial>
      <mass value="0.03264"/>
      <origin xyz="0.1384 -0.004609 0.0"/>
      <inertia ixx="0.00016" ixy="-0.0" ixz="0.0" iyy="0.00031" iyz="-0.0" izz="0.00024"/>
    </inertial>    
  </link>

  <link name="right_hand_t">
    <visual>
      <geometry>
        <mesh filename="meshes/v2/f13.obj"/>
      </geometry>
    </visual>
    <collision>
      <geometry>
        <mesh filename="meshes/v2/f13.obj"/>
      </geometry>
    </collision>
    <!-- <inertial>
      <mass value="0.0324"/>
      <origin xyz="0.102924 0.000592 0.0"/>
      <inertia ixx="9e-05" ixy="-1e-05" ixz="-0.0" iyy="0.00017" iyz="0.0" izz="0.00017"/>
    </inertial>
  </inertial>  -->
  <!-- Initial values make the inertia mass matrix not invertible as below floating point precision 
  for determinant, so we assume a default regularized version... -->
  <inertial>
    <mass value="0.0324" />
    <origin xyz="0.102924 0.000592 0.0"/>
    <inertia ixx="0.001" ixy="0.0" ixz="0.0" iyy="0.001" iyz="0.0" izz="0.001" />
  </inertial>    
  </link>

  <!-- MIDDLE FINGER LINKS -->
  <link name="right_hand_virtual_k">
    <visual>
      <origin xyz="0 0 0.01321"/>
      <geometry>
        <mesh filename="meshes/v2/f20.obj"/>
      </geometry>
    </visual>
    <collision>
      <origin xyz="0 0 0.01321"/>
      <geometry>
        <mesh filename="meshes/v2/f20.obj"/>
      </geometry>
    </collision>    
    <!-- <inertial>
      <mass value="0.02377"/>
      <origin xyz="0.003357 -8e-06 -0.099643"/>
      <inertia ixx="0.00021" ixy="-0.0" ixz="-1e-05" iyy="0.00011" iyz="0.0" izz="0.00019"/>
    </inertial> -->
    <!-- Initial values make the inertia mass matrix not invertible as below floating point precision 
    for determinant, so we assume a default regularized version... -->
    <inertial>
      <mass value="0.02377" />
      <origin xyz="0.003357 -8e-06 -0.099643"/>
      <inertia ixx="0.001" ixy="0.0" ixz="0.0" iyy="0.001" iyz="0.0" izz="0.001" />
    </inertial>        
  </link>

  <link name="right_hand_k">
    <visual>
      <geometry>
        <mesh filename="meshes/v2/f21.obj"/>
      </geometry>
    </visual>
    <collision>
      <geometry>
        <mesh filename="meshes/v2/f21.obj"/>
      </geometry>
    </collision>
    <inertial>
      <mass value="0.13474"/>
      <origin xyz="0.271122 0.00413 0.0"/>
      <inertia ixx="0.00052" ixy="-3e-05" ixz="-0.0" iyy="0.0037" iyz="-0.0" izz="0.0038"/>
    </inertial>
  </link>

  <link name="right_hand_o">
    <visual>
      <geometry>
        <mesh filename="meshes/v2/f22.obj"/>
      </geometry>
    </visual>
    <collision>
      <geometry>
        <mesh filename="meshes/v2/f22.obj"/>
      </geometry>
    </collision>    
    <inertial>
      <mass value="0.0422"/>
      <origin xyz="0.16683 -0.003774 0.0"/>
      <inertia ixx="0.0002" ixy="0.0" ixz="-0.0" iyy="0.00047" iyz="0.0" izz="0.0004"/>
    </inertial>   
  </link>

  <link name="right_hand_s">
    <visual>
      <geometry>
        <mesh filename="meshes/v2/f23.obj"/>
      </geometry>
    </visual>
    <collision>
      <geometry>
        <mesh filename="meshes/v2/f23.obj"/>
      </geometry>
    </collision>    
    <!-- <inertial>
      <mass value="0.03239"/>
      <origin xyz="0.102794 0.00042 0.0"/>
      <inertia ixx="9e-05" ixy="-1e-05" ixz="0.0" iyy="0.00017" iyz="0.0" izz="0.00017"/>
    </inertial>  -->
    <!-- Initial values make the inertia mass matrix not invertible as below floating point precision 
    for determinant, so we assume a default regularized version... -->
    <inertial>
      <mass value="0.03239" />
      <origin xyz="0.102794 0.00042 0.0"/>
      <inertia ixx="0.001" ixy="0.0" ixz="0.0" iyy="0.001" iyz="0.0" izz="0.001" />
    </inertial>      
  </link>

  <!-- RING FINGER LINKS -->
  <link name="right_hand_virtual_j">
    <visual>
      <origin xyz="0 0 -0.01321"/>
      <geometry>
        <mesh filename="meshes/v2/f30.obj"/>
      </geometry>
    </visual>
    <collision>
      <origin xyz="0 0 -0.01321"/>
      <geometry>
        <mesh filename="meshes/v2/f30.obj"/>
      </geometry>
    </collision>    
    <!-- <inertial>
      <mass value="0.02377"/>
      <origin xyz="0.003805 0.000386 0.100079"/>
      <inertia ixx="0.00021" ixy="0.0" ixz="1e-05" iyy="0.00011" iyz="-0.0" izz="0.00019"/>
    </inertial> -->
    <!-- Initial values make the inertia mass matrix not invertible as below floating point precision 
    for determinant, so we assume a default regularized version... -->
    <inertial>
      <mass value="0.02377" />
      <origin xyz="0.003805 0.000386 0.100079"/>
      <inertia ixx="0.001" ixy="0.0" ixz="0.0" iyy="0.001" iyz="0.0" izz="0.001" />
    </inertial>         
  </link>

  <link name="right_hand_j">
    <visual>
      <geometry>
        <mesh filename="meshes/v2/f31.obj"/>
      </geometry>
    </visual>
    <collision>
      <geometry>
        <mesh filename="meshes/v2/f31.obj"/>
      </geometry>
    </collision>    
    <inertial>
      <mass value="0.1377"/>
      <origin xyz="0.258283 -0.00154 0.0"/>
      <inertia ixx="0.00055" ixy="0.00018" ixz="-0.0" iyy="0.00411" iyz="0.0" izz="0.00426"/>
    </inertial>    
  </link>

  <link name="right_hand_n">
    <visual>
      <geometry>
        <mesh filename="meshes/v2/f32.obj"/>
      </geometry>
    </visual>
    <collision>
      <geometry>
        <mesh filename="meshes/v2/f32.obj"/>
      </geometry>
    </collision>
    <inertial>
      <mass value="0.04207"/>
      <origin xyz="0.166851 -0.00362 0.0"/>
      <inertia ixx="0.00019" ixy="0.0" ixz="-0.0" iyy="0.00047" iyz="0.0" izz="0.0004"/>
    </inertial>
  </link>

  <link name="right_hand_r">
    <visual>
      <geometry>
        <mesh filename="meshes/v2/f33.obj"/>
      </geometry>
    </visual>
    <collision>
      <geometry>
        <mesh filename="meshes/v2/f33.obj"/>
      </geometry>
    </collision>
    <!-- <inertial>
      <mass value="0.03229"/>
      <origin xyz="0.102676 0.000301 0.0"/>
      <inertia ixx="9e-05" ixy="-1e-05" ixz="0.0" iyy="0.00017" iyz="-0.0" izz="0.00017"/>
    </inertial> -->
    <!-- Initial values make the inertia mass matrix not invertible as below floating point precision 
    for determinant, so we assume a default regularized version... -->
    <inertial>
      <mass value="0.03229"/>
      <origin xyz="0.102676 0.000301 0.0"/>
      <inertia ixx="0.001" ixy="0.0" ixz="0.0" iyy="0.001" iyz="0.0" izz="0.001" />
    </inertial>    
  </link>

  <!-- LITTLE FINGER LINKS -->
  <link name="right_hand_virtual_i">
    <visual>
      <origin xyz="0 0 -0.01321"/>
      <geometry>
        <mesh filename="meshes/v2/f40.obj"/>
      </geometry>
    </visual>
    <collision>
      <origin xyz="0 0 -0.01321"/>
      <geometry>
        <mesh filename="meshes/v2/f40.obj"/>
      </geometry>
    </collision>
    <!-- <inertial>
      <mass value="0.02377"/>
      <origin xyz="0.003653 4.4e-05 0.100085"/>
      <inertia ixx="0.00021" ixy="0.0" ixz="1e-05" iyy="0.00011" iyz="-0.0" izz="0.00019"/>
    </inertial> -->
    <!-- Initial values make the inertia mass matrix not invertible as below floating point precision 
    for determinant, so we assume a default regularized version... -->
    <inertial>
      <mass value="0.02377" />
      <origin xyz="0.003653 4.4e-05 0.100085"/>
      <inertia ixx="0.001" ixy="0.0" ixz="0.0" iyy="0.001" iyz="0.0" izz="0.001" />
    </inertial>
  </link>

  <link name="right_hand_i">
    <visual>
      <geometry>
        <mesh filename="meshes/v2/f41.obj"/>
      </geometry>
    </visual>
    <collision>
      <geometry>
        <mesh filename="meshes/v2/f41.obj"/>
      </geometry>
    </collision>
    <inertial>
      <mass value="0.12544"/>
      <origin xyz="0.232293 0.00622 0.0"/>
      <inertia ixx="0.00049" ixy="6e-05" ixz="-0.0" iyy="0.00316" iyz="0.0" izz="0.00328"/>
    </inertial>    
  </link>

  <link name="right_hand_m">
    <visual>
      <geometry>
        <mesh filename="meshes/v2/f42.obj"/>
      </geometry>
    </visual>
    <collision>
      <geometry>
        <mesh filename="meshes/v2/f42.obj"/>
      </geometry>
    </collision>
    <!-- <inertial>
      <mass value="0.02488"/>
      <origin xyz="0.119665 -0.009328 0.0"/>
      <inertia ixx="0.00013" ixy="-0.0" ixz="-0.0" iyy="0.00023" iyz="0.0" izz="0.00016"/>
    </inertial> -->
    <!-- Initial values make the inertia mass matrix not invertible as below floating point precision 
    for determinant, so we assume a default regularized version... -->
    <inertial>
      <mass value="0.02488" />
      <origin xyz="0.119665 -0.009328 0.0"/>
      <inertia ixx="0.001" ixy="0.0" ixz="0.0" iyy="0.001" iyz="0.0" izz="0.001" />
    </inertial>    
  </link>

  <link name="right_hand_q">
    <visual>
      <geometry>
        <mesh filename="meshes/v2/f43.obj"/>
      </geometry>
    </visual>
    <collision>
      <geometry>
        <mesh filename="meshes/v2/f43.obj"/>
      </geometry>
    </collision>
    <!-- <inertial>
      <mass value="0.03234"/>
      <origin xyz="0.102896 0.000307 0.0"/>
      <inertia ixx="9e-05" ixy="-1e-05" ixz="-0.0" iyy="0.00017" iyz="0.0" izz="0.00017"/>
    </inertial> -->
    <!-- Initial values make the inertia mass matrix not invertible as below floating point precision 
    for determinant, so we assume a default regularized version... -->
    <inertial>
      <mass value="0.03234" />
      <origin xyz="0.102896 0.000307 0.0"/>
      <inertia ixx="0.001" ixy="0.0" ixz="0.0" iyy="0.001" iyz="0.0" izz="0.001" />
    </inertial>        
  </link>

  <joint name="right_hand_Thumb_Flexion" type="revolute">
    <parent link="right_hand_virtual_a"/>
    <child link="right_hand_a"/>
    <limit effort="1000.0" lower="0.0" upper="0.9704" velocity="1"/>
    <origin xyz="0 0 0" rpy="0 0 -0.9704" />
    <axis xyz="0 0 1"/>
  </joint>

  <joint name="right_hand_Thumb_Helper" type="fixed">
    <parent link="right_hand_z" />
    <child link="right_hand_virtual_a" />
    <origin xyz="0 0 0.04596" rpy="0 -1.5707 3.1416" />
  </joint>

  <!-- BASE_LINE JOINTS -->
  <joint name="right_hand_Thumb_Opposition" type="revolute">
    <parent link="right_hand_e1"/>
    <child link="right_hand_z"/>
    <limit effort="1000.0" lower="0.0" upper="0.9879" velocity="1"/>
    <origin xyz="-0.01690 0.02626 0" rpy="0 0.2618 1.571" />
    <axis xyz="0 0 -1"/>
  </joint>

  <!-- JOINT NOT FOR BASE_LINE. BUT WRITTEN DOWN HERE FOR BETTER UX -->
  
  <joint name="right_hand_f1" type="fixed">
    <parent link="right_hand_e1" />
    <child link="right_hand_d" />
    <origin xyz="0 0 0" rpy="0 0 0" />
  </joint>

  <joint name="right_hand_f2" type="fixed">
    <parent link="right_hand_d" />
    <child link="right_hand_h" />
    <origin xyz="0 0 0" rpy="0 0 0" />
  </joint>

  <joint name="right_hand_f3" type="fixed">
    <parent link="right_hand_h" />
    <child link="right_hand_d2" />
    <origin xyz="0 0 0" rpy="0 0 0" />
  </joint>

  <joint name="right_hand_f4" type="fixed">
    <parent link="right_hand_base_link"/>
    <child link="right_hand_e1"/>
    <origin xyz="0 -0.01313 0" rpy="0 0 0" />
  </joint>

  <joint name="right_hand_j5" type="revolute">
    <parent link="right_hand_e1"/>
    <child link="right_hand_e2"/>
    <limit effort="1000.0" lower="0.0" upper="0.98786" velocity="1"/>
    <origin xyz="0.0184 0.006 0.0375" rpy="0 0 0" />
    <axis xyz="0 0 1"/>
    <mimic joint="right_hand_Thumb_Opposition" multiplier="1" offset="0"/>
  </joint>

  <joint name="right_hand_f5" type="fixed">
    <parent link="right_hand_e2" />
    <child link="right_hand_e3" />
    <origin xyz="0 -0.0060 0" rpy="0 0 0" />
  </joint>

  <joint name="right_hand_f6" type="fixed">
    <parent link="right_hand_e3" />
    <child link="right_hand_e" />
    <origin xyz="0 0 0" rpy="0 0 0" />
  </joint>

  <joint name="right_hand_f7" type="fixed">
    <parent link="right_hand_e" />
    <child link="right_hand_e4" />
    <origin xyz="0 0 0" rpy="0 0 0" />
  </joint>

  <joint name="right_hand_f8" type="fixed">
    <parent link="right_hand_e" />
    <child link="right_hand_e5" />
    <origin xyz="0 0 0" rpy="0 0 0" />
  </joint>
  
  <!-- THUMB JOINTS -->
  <joint name="right_hand_j3" type="revolute">
    <parent link="right_hand_a"/>
    <child link="right_hand_b"/>
    <limit effort="1000.0" lower="0.0" upper="0.98506" velocity="1"/>
    <origin xyz="0.0485 0 0" rpy="0 0 0" />
    <axis xyz="0 0 1"/>
    <mimic joint="right_hand_Thumb_Flexion" multiplier="1.01511" offset="0"/>
  </joint>

  <joint name="right_hand_j4" type="revolute">
    <parent link="right_hand_b"/>
    <child link="right_hand_c"/>
    <limit effort="1000.0" lower="0.0" upper="1.406" velocity="1"/>
    <origin xyz="0.030 0 0" rpy="0 0 0" />
    <axis xyz="0 0 1"/>
    <mimic joint="right_hand_Thumb_Flexion" multiplier="1.44889" offset="0"/>
  </joint>

  <!-- INDEX FINGER JOINTS -->
  <joint name="right_hand_Index_Finger_Distal" type="revolute">
    <parent link="right_hand_l"/>
    <child link="right_hand_p"/>
    <limit effort="1000.0" lower="0" upper="1.334" velocity="1"/>
    <origin xyz="0.04804 0 0" rpy="0 0 0" />
    <axis xyz="0 0 1"/>
  </joint>

  <joint name="right_hand_Index_Finger_Proximal" type="revolute">
    <parent link="right_hand_virtual_l"/>
    <child link="right_hand_l"/>
    <limit effort="1000.0" lower="0.0" upper="0.79849" velocity="1"/>
    <origin xyz="0 0 0" rpy="-1.5707 0 0" />
    <axis xyz="0 0 1"/>
  </joint>

  <!-- JOINT Finger_Spread in BASE_LINE section for better UX -->
  <joint name="right_hand_j14" type="revolute">
    <parent link="right_hand_p"/>
    <child link="right_hand_t"/>
    <limit effort="1000.0" lower="0" upper="1.394" velocity="1"/>
    <origin xyz="0.026 0 0" rpy="0 0 0" />
    <axis xyz="0 0 1"/>
    <mimic joint="right_hand_Index_Finger_Distal" multiplier="1.0450" offset="0"/>
  </joint>

  <!-- MIDDLE FINGER JOINTS -->
  <joint name="right_hand_Middle_Finger_Proximal" type="revolute">
    <parent link="right_hand_virtual_k"/>
    <child link="right_hand_k"/>
    <limit effort="1000.0" lower="0.0" upper="0.79849" velocity="1"/>
    <origin xyz="0 0 0" rpy="-1.5707 0 0" />
    <axis xyz="0 0 1"/>
  </joint>

  <joint name="right_hand_Middle_Finger_Distal" type="revolute">
    <parent link="right_hand_k"/>
    <child link="right_hand_o"/>
    <limit effort="1000.0" lower="0" upper="1.334" velocity="1"/>
    <origin xyz="0.05004 0 0" rpy="0 0 0" />
    <axis xyz="0 0 1"/>
  </joint>

  <joint name="right_hand_j15" type="revolute">
    <parent link="right_hand_o"/>
    <child link="right_hand_s"/>
    <limit effort="1000.0" lower="0" upper="1.334" velocity="1"/>
    <origin xyz="0.032 0 0" rpy="0 0 0" />
    <axis xyz="0 0 1"/>
    <mimic joint="right_hand_Middle_Finger_Distal" multiplier="1.0454" offset="0"/>
  </joint>

  <!-- RING FINGER JOINTS -->
  <joint name="right_hand_Ring_Finger" type="revolute">
    <parent link="right_hand_virtual_j"/>
    <child link="right_hand_j"/>
    <limit effort="1000.0" lower="0.0" upper="0.98175" velocity="1"/>
    <origin xyz="0 0 0" rpy="1.5707 0 0" />
    <axis xyz="0 0 1"/>
  </joint>

  <joint name="right_hand_j12" type="revolute">
    <parent link="right_hand_j"/>
    <child link="right_hand_n"/>
    <limit effort="1000.0" lower="0" upper="1.334" velocity="1"/>
    <origin xyz="0.05004 0 0" rpy="0 0 0" />
    <axis xyz="0 0 1"/>
    <mimic joint="right_hand_Ring_Finger" multiplier="1.3588" offset="0"/>
  </joint>

  <joint name="right_hand_j16" type="revolute">
    <parent link="right_hand_n"/>
    <child link="right_hand_r"/>
    <limit effort="1000.0" lower="0" upper="1.395" velocity="1"/>
    <origin xyz="0.032 0 0" rpy="0 0 0" />
    <axis xyz="0 0 1"/>
    <mimic joint="right_hand_Ring_Finger" multiplier="1.42093" offset="0"/>
  </joint>

  <!-- PINKY JOINTS -->
  <joint name="right_hand_Pinky" type="revolute">
    <parent link="right_hand_virtual_i"/>
    <child link="right_hand_i"/>
    <limit effort="1000.0" lower="0.0" upper="0.98175" velocity="1"/>
    <origin xyz="0 0 0" rpy="1.5707 0 0" />
    <axis xyz="0 0 1"/>
  </joint>

  <joint name="right_hand_j13" type="revolute">
    <parent link="right_hand_i"/>
    <child link="right_hand_m"/>
    <limit effort="1000.0" lower="0" upper="1.334" velocity="1"/>
    <origin xyz="0.04454 0 0" rpy="0 0 0" />
    <axis xyz="0 0 1"/>
    <mimic joint="right_hand_Pinky" multiplier="1.35880" offset="0"/>
  </joint>

  <joint name="right_hand_j17" type="revolute">
    <parent link="right_hand_m"/>
    <child link="right_hand_q"/>
    <limit effort="1000.0" lower="0" upper="1.3971" velocity="1"/>
    <origin xyz="0.022 0 0" rpy="0 0 0" />
    <axis xyz="0 0 1"/>
    <mimic joint="right_hand_Pinky" multiplier="1.42307" offset="0"/>
  </joint>

  <joint name="right_hand_index_spread" type="revolute">
    <parent link="right_hand_d2"/>
    <child link="right_hand_virtual_l"/>
    <limit effort="1000.0" lower="0.0" upper="0.28833" velocity="1"/>
    <origin xyz="-0.025 0 0.110" rpy="0 -1.5707 1.5707" />
    <axis xyz="0 0 1"/>
    <mimic joint="right_hand_Finger_Spread" multiplier="0.5" offset="0"/>
  </joint>

  <joint name="right_hand_middle_spread_dummy" type="fixed">
    <parent link="right_hand_d"/>
    <child link="right_hand_virtual_k"/>
    <origin xyz="0 0 0.110" rpy="0 -1.5707 1.5707" />
  </joint>

  <joint name="right_hand_ring_spread" type="revolute">
    <parent link="right_hand_e5"/>
    <child link="right_hand_virtual_j"/>
    <limit effort="1000.0" lower="0.0" upper="0.28833" velocity="1"/>
    <origin xyz="0.003855 0 0.0655" rpy="-1.5707 -1.5707 0" />
    <axis xyz="0 0 1"/>
    <mimic joint="right_hand_Finger_Spread" multiplier="0.5" offset="0"/>
  </joint>

  <joint name="right_hand_Finger_Spread" type="revolute">
    <parent link="right_hand_e4"/>
    <child link="right_hand_virtual_i"/>
    <limit effort="1000.0" lower="0.0" upper="0.5829" velocity="1"/>
    <origin xyz="0.025355 0 0.056" rpy="-1.5707 -1.5707 0" />
    <axis xyz="0 0 1"/>
  </joint>

  <link name="thtip"/>
  <link name="fftip"/>
  <link name="mftip"/>
  <link name="rftip"/>
  <link name="lftip"/>
  <joint name="thtip_joint" type="fixed">
    <parent link="right_hand_c"/>
    <child link="thtip"/>
    <origin rpy="0.00000 -0.00000 0.00000" xyz="0.0275 0.000 0.000"/>
  </joint>
  <joint name="fftip_joint" type="fixed">
    <parent link="right_hand_t"/>
    <child link="fftip"/>
    <origin rpy="0.00000 -0.00000 0.00000" xyz="0.014 0.000 0.000"/>
  </joint>
  <joint name="mftip_joint" type="fixed">
    <parent link="right_hand_s"/>
    <child link="mftip"/>
    <origin rpy="0.00000 -0.00000 0.00000" xyz="0.014 0.000 0.000"/>
  </joint>
  <joint name="rftip_joint" type="fixed">
    <parent link="right_hand_r"/>
    <child link="rftip"/>
    <origin rpy="0.00000 -0.00000 0.00000" xyz="0.014 0.000 0.000"/>
  </joint>
  <joint name="lftip_joint" type="fixed">
    <parent link="right_hand_q"/>
    <child link="lftip"/>
    <origin rpy="0.00000 -0.00000 0.00000" xyz="0.014 0.000 0.000"/>
  </joint>
</robot>

